Workbook

Sheet Summary
A1: Tony Greenberg site — Next.js migration status
A2: Generated from NEXTJS-MIGRATION-TODO.md on 2026-10-17 by scripts/build-migration-status-report.py — a living document; re-run the script after updating the todo file. Counts are formulas over the Full Detail tab.
A4: Phase | B4: Done | C4: Remaining | D4: Deferred | E4: Total | F4: % Complete
A5: Phase 0 — Bootstrap | B5: =COUNTIFS('Full Detail'!$E$2:$E$361,$A5,'Full Detail'!$C$2:$C$361,"Done") | C5: =COUNTIFS('Full Detail'!$E$2:$E$361,$A5,'Full Detail'!$C$2:$C$361,"Remaining") | D5: =COUNTIFS('Full Detail'!$E$2:$E$361,$A5,'Full Detail'!$C$2:$C$361,"Deferred") | E5: =SUM(B5:D5) | F5: =IF(E5=0,0,B5/E5)
A6: Phase 1 — Sanity Studio & Schema | B6: =COUNTIFS('Full Detail'!$E$2:$E$361,$A6,'Full Detail'!$C$2:$C$361,"Done") | C6: =COUNTIFS('Full Detail'!$E$2:$E$361,$A6,'Full Detail'!$C$2:$C$361,"Remaining") | D6: =COUNTIFS('Full Detail'!$E$2:$E$361,$A6,'Full Detail'!$C$2:$C$361,"Deferred") | E6: =SUM(B6:D6) | F6: =IF(E6=0,0,B6/E6)
A7: Phase 2 — Supabase | B7: =COUNTIFS('Full Detail'!$E$2:$E$361,$A7,'Full Detail'!$C$2:$C$361,"Done") | C7: =COUNTIFS('Full Detail'!$E$2:$E$361,$A7,'Full Detail'!$C$2:$C$361,"Remaining") | D7: =COUNTIFS('Full Detail'!$E$2:$E$361,$A7,'Full Detail'!$C$2:$C$361,"Deferred") | E7: =SUM(B7:D7) | F7: =IF(E7=0,0,B7/E7)
A8: Phase 3 — Shared Layout & Design System | B8: =COUNTIFS('Full Detail'!$E$2:$E$361,$A8,'Full Detail'!$C$2:$C$361,"Done") | C8: =COUNTIFS('Full Detail'!$E$2:$E$361,$A8,'Full Detail'!$C$2:$C$361,"Remaining") | D8: =COUNTIFS('Full Detail'!$E$2:$E$361,$A8,'Full Detail'!$C$2:$C$361,"Deferred") | E8: =SUM(B8:D8) | F8: =IF(E8=0,0,B8/E8)
A9: Phase 4 — Marketing Core Pages (30 routes) | B9: =COUNTIFS('Full Detail'!$E$2:$E$361,$A9,'Full Detail'!$C$2:$C$361,"Done") | C9: =COUNTIFS('Full Detail'!$E$2:$E$361,$A9,'Full Detail'!$C$2:$C$361,"Remaining") | D9: =COUNTIFS('Full Detail'!$E$2:$E$361,$A9,'Full Detail'!$C$2:$C$361,"Deferred") | E9: =SUM(B9:D9) | F9: =IF(E9=0,0,B9/E9)
A10: Phase 5 — Blog Engine (Sanity-backed) | B10: =COUNTIFS('Full Detail'!$E$2:$E$361,$A10,'Full Detail'!$C$2:$C$361,"Done") | C10: =COUNTIFS('Full Detail'!$E$2:$E$361,$A10,'Full Detail'!$C$2:$C$361,"Remaining") | D10: =COUNTIFS('Full Detail'!$E$2:$E$361,$A10,'Full Detail'!$C$2:$C$361,"Deferred") | E10: =SUM(B10:D10) | F10: =IF(E10=0,0,B10/E10)
A11: Phase 6 — BrewSoul (28 routes) | B11: =COUNTIFS('Full Detail'!$E$2:$E$361,$A11,'Full Detail'!$C$2:$C$361,"Done") | C11: =COUNTIFS('Full Detail'!$E$2:$E$361,$A11,'Full Detail'!$C$2:$C$361,"Remaining") | D11: =COUNTIFS('Full Detail'!$E$2:$E$361,$A11,'Full Detail'!$C$2:$C$361,"Deferred") | E11: =SUM(B11:D11) | F11: =IF(E11=0,0,B11/E11)
A12: Phase 7 — PRI & Kava Encyclopedias (19 routes) | B12: =COUNTIFS('Full Detail'!$E$2:$E$361,$A12,'Full Detail'!$C$2:$C$361,"Done") | C12: =COUNTIFS('Full Detail'!$E$2:$E$361,$A12,'Full Detail'!$C$2:$C$361,"Remaining") | D12: =COUNTIFS('Full Detail'!$E$2:$E$361,$A12,'Full Detail'!$C$2:$C$361,"Deferred") | E12: =SUM(B12:D12) | F12: =IF(E12=0,0,B12/E12)
A13: Phase 8 — Attention Theft Manifesto (7 routes) | B13: =COUNTIFS('Full Detail'!$E$2:$E$361,$A13,'Full Detail'!$C$2:$C$361,"Done") | C13: =COUNTIFS('Full Detail'!$E$2:$E$361,$A13,'Full Detail'!$C$2:$C$361,"Remaining") | D13: =COUNTIFS('Full Detail'!$E$2:$E$361,$A13,'Full Detail'!$C$2:$C$361,"Deferred") | E13: =SUM(B13:D13) | F13: =IF(E13=0,0,B13/E13)
A14: Phase 9 — Assessments (33 routes) | B14: =COUNTIFS('Full Detail'!$E$2:$E$361,$A14,'Full Detail'!$C$2:$C$361,"Done") | C14: =COUNTIFS('Full Detail'!$E$2:$E$361,$A14,'Full Detail'!$C$2:$C$361,"Remaining") | D14: =COUNTIFS('Full Detail'!$E$2:$E$361,$A14,'Full Detail'!$C$2:$C$361,"Deferred") | E14: =SUM(B14:D14) | F14: =IF(E14=0,0,B14/E14)
A15: Phase 10 — FauxTony Chatbot — CANCELLED (2026-09-10) | B15: =COUNTIFS('Full Detail'!$E$2:$E$361,$A15,'Full Detail'!$C$2:$C$361,"Done") | C15: =COUNTIFS('Full Detail'!$E$2:$E$361,$A15,'Full Detail'!$C$2:$C$361,"Remaining") | D15: =COUNTIFS('Full Detail'!$E$2:$E$361,$A15,'Full Detail'!$C$2:$C$361,"Deferred") | E15: =SUM(B15:D15) | F15: =IF(E15=0,0,B15/E15)
A16: Phase 11 — Code MCP Server — REBUILT (2026-09-29) | B16: =COUNTIFS('Full Detail'!$E$2:$E$361,$A16,'Full Detail'!$C$2:$C$361,"Done") | C16: =COUNTIFS('Full Detail'!$E$2:$E$361,$A16,'Full Detail'!$C$2:$C$361,"Remaining") | D16: =COUNTIFS('Full Detail'!$E$2:$E$361,$A16,'Full Detail'!$C$2:$C$361,"Deferred") | E16: =SUM(B16:D16) | F16: =IF(E16=0,0,B16/E16)
... A19: Phase 14 — QA & Launch | B19: =COUNTIFS('Full Detail'!$E$2:$E$361,$A19,'Full Detail'!$C$2:$C$361,"Done") | C19: =COUNTIFS('Full Detail'!$E$2:$E$361,$A19,'Full Detail'!$C$2:$C$361,"Remaining") | D19: =COUNTIFS('Full Detail'!$E$2:$E$361,$A19,'Full Detail'!$C$2:$C$361,"Deferred") | E19: =SUM(B19:D19) | F19: =IF(E19=0,0,B19/E19)
A20: TOTAL | B20: =SUM(B5:B19) | C20: =SUM(C5:C19) | D20: =SUM(D5:D19) | E20: =SUM(E5:E19) | F20: =IF(E20=0,0,B20/E20)

Sheet Full Detail
A1: Phase | B1: Route / Item | C1: Status | D1: Notes | E1: Phase name
A2: Phase 0 — Bootstrap
B3: Scaffold Next.js 16 (App Router, TypeScript, Tailwind v4, src/ dir, @/* import alias) at web/ | C3: Done | E3: Phase 0 — Bootstrap
B4: Initialize shadcn/ui (Radix base, Nova preset, CSS variables) | C4: Done | E4: Phase 0 — Bootstrap
B5: Install core UI components (button, card, dialog, sheet, dropdown-menu, accordion, tabs, avatar, tooltip, separator, select, checkbox, radio… | C5: Done | D5: -group, switch, popover, navigation-menu, badge, input, label, skeleton, progress, alert, scroll-area, carousel, aspect-ratio, hover-card, sonner, slider, toggle, toggle-group) | E5: Phase 0 — Bootstrap
B6: Install Sanity (sanity, next-sanity, @sanity/image-url, @sanity/vision, @portabletext/react) | C6: Done | E6: Phase 0 — Bootstrap
B7: Install Supabase (@supabase/supabase-js, @supabase/ssr) | C7: Done | E7: Phase 0 — Bootstrap
B8: Install zod, react-hook-form, @hookform/resolvers, date-fns, next-themes, @anthropic-ai/sdk, reading-time | C8: Done | E8: Phase 0 — Bootstrap
B9: Fix pnpm-workspace.yaml allowBuilds (esbuild, sharp → true) | C9: Done | E9: Phase 0 — Bootstrap
B10: Configure next.config.ts images.remotePatterns (Sanity CDN + legacy Manus/CloudFront hosts, temporary) | C10: Done | E10: Phase 0 — Bootstrap
B11: Read Next.js 16 bundled docs (node_modules/next/dist/docs/) for breaking changes vs | C11: Done | D11: Next 13-15 (proxy.ts vs middleware.ts, Promise params, cache directives, Image config defaults) — confirmed, documented in agent notes | E11: Phase 0 — Bootstrap
B12: pnpm install clean, pnpm dev boots with no errors (verified | C12: Done | D12: Turbopack ready in 375ms, HTTP 200) | E12: Phase 0 — Bootstrap
B13: Add .env.local.example documenting every env var this app needs (Sanity project ID/dataset/token, Supabase URL/anon/service keys, Anthropic API key, site URL) | C13: Done | E13: Phase 0 — Bootstrap
B14: web/README.md rewritten | C14: Done | D14: what this app is, how it relates to the legacy app at the repo root, how to run it, how Sanity/Supabase are wired, Next.js 16 breaking-change notes | E14: Phase 0 — Bootstrap
A15: Phase 1 — Sanity Studio & Schema
B16: Connected to an existing Sanity project already owned by the team ("Tonygreenberg", project ID a3q1cyqs, dataset production) | C16: Done | D16: found via an already-authenticated CLI session rather than creating a new one; recorded in web/.env.local | E16: Phase 1 — Sanity Studio & Schema
B17: Embed Studio at web/src/app/studio/[[...tool]]/page.tsx | C17: Done | E17: Phase 1 — Sanity Studio & Schema
B18: Schema | C18: Done | D18: post (title, slug, subtitle, excerpt, pullQuote, body [portable text], heroImage, author ref, category ref, tags[], publishedAt, readTime, seo) — actual path web/src/sanity/schemas/post.ts | E18: Phase 1 — Sanity Studio & Schema
B19: Schema | C19: Done | D19: author (name, slug, avatar, bio) | E19: Phase 1 — Sanity Studio & Schema
B20: Schema | C20: Done | D20: category (title, slug, description) | E20: Phase 1 — Sanity Studio & Schema
B21: Schema: page (title, slug, body, seo) | C21: Done | D21: for marketing pages that need CMS-editable copy | E21: Phase 1 — Sanity Studio & Schema
B22: Schema: seo object (metaTitle, metaDescription, keywords, ogImage, noIndex) | C22: Done | D22: reused across post/page/pageSeo | E22: Phase 1 — Sanity Studio & Schema
B23: Schema: pageSeo (route-keyed SEO override, not in the original plan | C23: Done | D23: added because this site has far more routes than a page document per route would suit; see the schema file for why) | E23: Phase 1 — Sanity Studio & Schema
B24: Schema | C24: Done | D24: siteSettings singleton (site title, tagline, logo, defaultSeo, navigation, footerColumns, footerText, socialLinks) | E24: Phase 1 — Sanity Studio & Schema
B25: Schema: redirect (source, destination, permanent) | C25: Done | D25: backs the Manus→Next.js 301 map (Phase 12) | E25: Phase 1 — Sanity Studio & Schema
B26: Sanity client + typed query helpers | C26: Done | D26: actual path web/src/lib/sanity/client.ts + queries.ts (not web/src/sanity/* as originally sketched here; schemas live in src/sanity/, app-facing read code lives in src/lib/sanity/) | E26: Phase 1 — Sanity Studio & Schema
B27: Sanity image URL builder helper (web/src/lib/sanity/image.ts) wrapping @sanity/image-url, used by next/image everywhere | C27: Done | E27: Phase 1 — Sanity Studio & Schema
B28: Write one-off migration script (web/scripts/migrate-blog-posts.ts, pnpm migrate:blog [--dry-run]) | C28: Done | D28: reads client/src/data/blogData.json (121 posts) → creates Sanity post documents, idempotent by deterministic _id (skips posts that already exist) | E28: Phase 1 — Sanity Studio & Schema
B29: Ran the migration: 121/121 posts created, 0 errors | C29: Done | D29: Author (Tony Greenberg) and 9 categories auto-created. 22 posts got a real hero image uploaded (17 already on RampRate's own CloudFront + 4 rescued live from the legacy /api/img/ proxy + 1 rescued from /manus-storage/ before Manus is decommissioned). 99 posts have no hero image yet — tracked per-post in BLOG-IMAGE-BRIEFS.md with a suggested generation prompt for each; check them off there as real art goes in via Studio | E29: Phase 1 — Sanity Studio & Schema
B30: Spot-check 5-10 migrated posts in Studio (/studio) | C30: Done | D30: verify body formatting (headings/lists/links) came through correctly from the markdown conversion. Done 2026-10-02 on 30 posts, ours vs live: text and links came through (word counts within 2%, same link counts), but the import kept single-line-break lines inside one block (119 blocks in 78 of 121 posts; one 7,932 characters), so posts ran together and lost ~500 short section headings that live shows. Fixed at render time in src/lib/sanity/legacy-body.ts (one paragraph per line; legacy's "short title-like line = section heading" rule for posts created before 2026-10-02, never for a line with a web address), run before autoLinkBody on /blog/[slug]. No Sanity drafts needed. Re-checked: 145 of 162 live headings now match on 30 posts (was ~0 of the plain ones); the rest are live's own quirks (raw #/ Markdown showing on live) or headings already styled in Sanity. | E30: Phase 1 — Sanity Studio & Schema
B31: Real bug found and fixed | C31: Done | D31: markdown-to-portable-text.ts's list-item conversion only ever looked for a "text"-type token inside item.tokens; marked wraps any "loose" list item (one followed by a body paragraph on the next line — e.g. five-cups' "Five Questions Worth Sitting With") in a "paragraph" token instead, so every such item silently converted to an empty Portable Text block (visible live as a bare, contentless numbered list). Fixed the converter to handle both token shapes, then wrote scripts/backfill-list-item-content.ts (idempotent, patches only body) and ran it against all 121 already-migrated posts — 6 posts had at least one empty list item; all 6 fixed in place. | E31: Phase 1 — Sanity Studio & Schema
A32: Phase 2 — Supabase
B33: Supabase project created (2026-10-01): tonygreenberg (free plan, West US), https://zukaqnbknrsmixjvozlj.supabase.co | C33: Done | D33: URL, publishable key (in NEXT_PUBLIC_SUPABASE_ANON_KEY, the name the code reads) and secret key are in .env.local; all three checked against Supabase's API. Not yet in Netlify (its three Supabase settings are still empty). With the keys set, src/proxy.ts is active locally: a production build still serves every page (checked /, /blog, a post, /the-letter, /living-declaration, /america-unbundled, /studio, /login, redirects, 404s). Found: supabase/migrations/0001_init.sql isn't in the repo (the folder is empty), so no tables exist yet, and /login sends a signed-in user to /dashboard/approvals, which was never built (the approval dashboard was replaced by the MCP server). Needs a decision on what Supabase is for before tables or accounts are made. | E33: Phase 2 — Supabase
B34: web/src/lib/supabase/server.ts (SSR client for Server Components/Actions, current getAll/setAll cookie API) and client.ts (browser client) helpers | C34: Done | E34: Phase 2 — Supabase
B35: web/src/lib/supabase/service-role.ts | C35: Done | D35: bypasses RLS, server-only, for chat logging (not in the original plan, but required to satisfy "service-role write only, no public read" below) | E35: Phase 2 — Supabase
B36: web/src/proxy.ts | C36: Done | D36: Supabase's required session-refresh middleware, renamed to proxy.ts per Next.js 16. Ships with a guard: if NEXT_PUBLIC_SUPABASE_URL/_ANON_KEY aren't set yet, it no-ops instead of throwing — without that guard it took the entire site down (every route 500'd) the moment it was added, since it ran on every request. Safe to leave in place; it activates automatically once real credentials land in .env.local | E36: Phase 2 — Supabase
B37: Auth: email/password login for internal approvers | C37: Done | D37: web/src/app/(auth)/login/page.tsx + login-form.tsx + actions.ts (Server Action via useActionState, real spinner on submit per the loader rule in CONTRIBUTING.md, not text). Renders correctly now (verified: HTTP 200, real form) but signing in will fail until the Supabase project above actually exists | E37: Phase 2 — Supabase
B38: SQL migration written (web/supabase/migrations/0001_init.sql) | C38: Done | D38: change_requests table, chat_conversations + chat_messages tables, RLS enabled on all three. Not yet run against a live database — needs the project above first (supabase db push once the CLI is linked, or paste into the SQL editor) | E38: Phase 2 — Supabase
B39: Row-level security policies written in that same migration | C39: Done | D39: authenticated-only read/write on change_requests (noted in-file to scope tighter than "any authenticated user" once more accounts exist); chat tables get RLS enabled with zero policies for anon/authenticated, which is what actually enforces "service-role write only, no public read" (service role bypasses RLS entirely — that's not a policy, it's the point) | E39: Phase 2 — Supabase
B40: Member accounts (2026-10-06, owner chose email + password) | C40: Done | D40: /login, /signup, /forgot-password, /reset-password, /auth/callback (confirm/reset email links; records an invite referral on first confirm). Server actions in src/app/(auth)/actions.ts; Formik + Yup on the 3-field forms; helpers in src/lib/auth.ts (getUser, requireUser, isAdmin via ADMIN_EMAILS), src/lib/supabase/service-role.ts, src/lib/referrals.ts. The old internal-approver login (redirected to a dashboard that was never built) is replaced. Tested on a production build: pages, form checks, wrong-password message, redirects. Not tested: a real sign-up (would create a real account and send a real email). | E40: Phase 2 — Supabase
...

Sheet Remaining Work
A1: Phase | B1: Route / Item | C1: Status | D1: Why it's not done / what's blocking it | E1: Phase name
A2: Phase 4 — Marketing Core Pages (30 routes)
B3: /shop, /payment-success, /payment-cancel | C3: Deferred | D3: defer: (2026-10-13: /shop temporarily redirects to /subscribe; delete that entry in SEARCH_CONSOLE_TEMPORARY_REDIRECTS when this is built) these are Stripe-backed; flag for the later billing-migration phase, do not port checkout logic yet, static/informational content only if ported now | E3: Phase 4 — Marketing Core Pages (30 routes)
A4: Phase 11 — Code MCP Server — REBUILT (2026-09-29)
B5: Set GITHUB_TOKEN, MCP_ADMIN_USERS, MCP_LOGIN_PASSWORD, MCP_OAUTH_SECRET, MCP_SITE_ORIGIN, MCP_PUBLIC_ORIGIN in Netlify (done) (checked 2026-… | C5: Remaining | D5: 10-07: all already set in Netlify). Left: connect Claude.ai to /api/mcp for real, and verify the GitHub flow end to end (branch → PR → deploy preview → publish_changes) against a real PR. | E5: Phase 11 — Code MCP Server — REBUILT (2026-09-29)
B6: Commit a team-wide .mcp.json (URL only) once the production URL is settled. | C6: Remaining | E6: Phase 11 — Code MCP Server — REBUILT (2026-09-29)
B7: Test the new review end to end on a deploy preview | C7: Remaining | D7: (needs a yes, it opens a real pull request): one throwaway change from Claude.ai or ChatGPT: start (unclear request, so the confirm step shows), confirm, edit, review card, screenshots, upload link, then discard. | E7: Phase 11 — Code MCP Server — REBUILT (2026-09-29)
A8: Phase 12 — SEO Hardening, Redirects & Cutover Prep
B9: Connect Google Search Console + GA4 to the new deployment on day one of cutover | C9: Remaining | E9: Phase 12 — SEO Hardening, Redirects & Cutover Prep
A10: Phase 14 — QA & Launch
B11: Find Your Me: pick real essays for two results (2026-10-16), needs Tony | C11: Remaining | D11: The Systems | E11: Phase 14 — QA & Launch
B12: Quiz content questions for Tony (2026-10-16) | C12: Remaining | D12: Consciousness Scale: the answer scores only | E12: Phase 14 — QA & Launch
B13: DNS cutover, legacy app decommissioned only after a stable overlap window Re-checked 2026-10-13 | C13: Remaining | D13: unchanged (Hostinger name servers, bare domain on Manus 104.19.168/169.112, www CNAME cname.manus.space). Checked 2026-10-09 (owner wants to go live and switch off Manus): DNS for tonygreenberg.com is at Hostinger (name servers ns1/ns2.dns-parking.com); www is a CNAME to cname.manus.space, the bare domain points at Manus's addresses (104.19.168.112 / .169.112); the Netlify site tonygreenberg-website has no custom domain yet (production branch main). Order: (1) merge the three open pull requests into main and check the Netlify copy; (2) restore Supabase and run 0001 to 0003, or launch without member features (they say "isn't available just now"); (3) owner sign-off; (4) add tonygreenberg.com + www in Netlify (Domain management), then at Hostinger point the bare domain at Netlify (A record 75.2.60.5, or Netlify DNS) and www CNAME at tonygreenberg-website.netlify.app; Netlify issues the HTTPS certificate; (5) re-run scripts/check-search-console-urls.ts https://tonygreenberg.com and submit the sitemap in Search Console; (6) only after a few stable days: switch off the Manus site (the database is already backed up, docs/ai/project_legacy_database.md) and rotate the old database password. | E13: Phase 14 — QA & Launch
